{"name": "test_5_timeout_exception_handling", "status": "passed", "start": 1710526154400, "stop": 1710526159509, "uuid": "f4e2cab9-8127-4a67-907a-a451dfb2e10e", "historyId": "be3a3e262b6eb4c474412f0666c2dbb3", "testCaseId": "be3a3e262b6eb4c474412f0666c2dbb3", "fullName": "Tests.test_exception.TestLogin#test_5_timeout_exception_handling", "labels": [{"name": "tag", "value": "@pytest.mark.usefixtures('setup_and_teardown', 'log_on_failure')"}, {"name": "parentSuite", "value": "Tests"}, {"name": "suite", "value": "test_exception"}, {"name": "subSuite", "value": "TestLogin"}, {"name": "host", "value": "DESKTOP-UEVTOM8"}, {"name": "thread", "value": "10492-MainThread"}, {"name": "framework", "value": "pytest"}, {"name": "language", "value": "cpython3"}, {"name": "package", "value": "Tests.test_exception"}]}