{"name": "test_5_timeout_exception_handling", "status": "passed", "start": 1710573238454, "stop": 1710573243503, "uuid": "3508a101-6b96-4fcc-9b78-da001aea6148", "historyId": "be3a3e262b6eb4c474412f0666c2dbb3", "testCaseId": "be3a3e262b6eb4c474412f0666c2dbb3", "fullName": "Tests.test_exception.TestLogin#test_5_timeout_exception_handling", "labels": [{"name": "tag", "value": "@pytest.mark.usefixtures('setup_and_teardown', 'log_on_failure')"}, {"name": "parentSuite", "value": "Tests"}, {"name": "suite", "value": "test_exception"}, {"name": "subSuite", "value": "TestLogin"}, {"name": "host", "value": "DESKTOP-UEVTOM8"}, {"name": "thread", "value": "4100-MainThread"}, {"name": "framework", "value": "pytest"}, {"name": "language", "value": "cpython3"}, {"name": "package", "value": "Tests.test_exception"}]}